<robot name="humanoid">
    <link name="head">
        <visual>
            <origin xyz="0 0 2.2" rpy="0 0 0"/>
            <geometry>
                <sphere radius="1.3"/>
            </geometry>
            <material name="blue">
                <color rgba="0 0 1 1"/>
            </material>
        </visual>
        <inertial>
            <mass value="0.533"/>
            <origin xyz="0 0 2.2" rpy="0 0 0"/>
            <inertia ixx="1" ixy="0" ixz="0" iyy="1" iyz="0" izz="1"/>
        </inertial>
        <collision>
            <origin xyz="0 0 2.2" rpy="0 0 0"/>
            <geometry>
                <sphere radius="1.3"/>
            </geometry>
        </collision>
    </link>

    <link name="chest">
        <visual>
            <origin xyz="0 0 12" rpy="0 0 0"/>
            <geometry>
                <sphere radius="1.6"/>
            </geometry>
            <material name="red">
                <color rgba="1 0 0 1"/>
            </material>
        </visual>
        <inertial>
            <mass value="2.275"/>
            <origin xyz="0 0 12" rpy="0 0 0"/>
            <inertia ixx="1" ixy="0" ixz="0" iyy="1" iyz="0" izz="1"/>
        </inertial>
        <collision>
            <origin xyz="0 0 12" rpy="0 0 0"/>
            <geometry>
                <sphere radius="1.6"/>
            </geometry>
        </collision>
    </link>

    <link name="hip">
        <visual>
            <origin xyz="0 0 -3.1" rpy="0 0 0"/>
            <geometry>
                <sphere radius="1.2"/>
            </geometry>
            <material name="green">
                <color rgba="0 1 0 1"/>
            </material>
        </visual>
        <inertial>
            <mass value="1.43"/>
            <origin xyz="0 0 -3.1" rpy="0 0 0"/>
            <inertia ixx="1" ixy="0" ixz="0" iyy="1" iyz="0" izz="1"/>
        </inertial>
        <collision>
            <origin xyz="0 0 -3.1" rpy="0 0 0"/>
            <geometry>
                <sphere radius="1.2"/>
            </geometry>
        </collision>
    </link>

    <link name="left_upper_arm">
        <visual>
            <origin xyz="0 0 -1.8" rpy="0 0 0"/>
            <geometry>
                <cylinder length="2.8" radius="0.5"/>
            </geometry>
            <material name="yellow">
                <color rgba="1 1 0 1"/>
            </material>
        </visual>
        <inertial>
            <mass value="0.38"/>
            <origin xyz="0 0 -1.8" rpy="0 0 0"/>
            <inertia ixx="1" ixy="0" ixz="0" iyy="1" iyz="0" izz="1"/>
        </inertial>
        <collision>
            <origin xyz="0 0 -1.8" rpy="0 0 0"/>
            <geometry>
                <cylinder length="2.7" radius="0.5"/>
            </geometry>
        </collision>
    </link>

    <link name="left_forearm">
        <visual>
            <origin xyz="-0.4 0 -1.6" rpy="0 0 0"/>
            <geometry>
                <cylinder length="2.6" radius="0.35"/>
            </geometry>
            <material name="orange">
                <color rgba="1 0.5 0 1"/>
            </material>
        </visual>
        <inertial>
            <mass value="0.19"/>
            <origin xyz="-0.4 0 -1.6" rpy="0 0 0"/>
            <inertia ixx="1" ixy="0" ixz="0" iyy="1" iyz="0" izz="1"/>
        </inertial>
        <collision>
            <origin xyz="-0.4 0 -1.6" rpy="0 0 0"/>
            <geometry>
                <cylinder length="2.8" radius="0.35"/>
            </geometry>
        </collision>
    </link>

    <link name="left_hand">
        <visual>
            <origin xyz="-0 0 0" rpy="0 0 0"/>
            <geometry>
                <sphere radius="0.5"/>
            </geometry>
            <material name="orange">
                <color rgba="1 0.5 0 1"/>
            </material>
        </visual>
        <inertial>
            <mass value="0.06"/>
            <origin xyz="0 0 0" rpy="0 0 0"/>
            <inertia ixx="1" ixy="0" ixz="0" iyy="1" iyz="0" izz="1"/>
        </inertial>
        <collision>
            <origin xyz="-0 0 0" rpy="0 0 0"/>
            <geometry>
                <sphere radius="0.5"/>
            </geometry>
        </collision>
    </link>

    <link name="right_upper_arm">
        <visual>
            <origin xyz="0 0 -1.8" rpy="0 0 0"/>
            <geometry>
                <cylinder length="2.8" radius="0.5"/>
            </geometry>
            <material name="yellow">
                <color rgba="1 1 0 1"/>
            </material>
        </visual>
        <inertial>
            <mass value="0.38"/>
            <origin xyz="0 0 -1.8" rpy="0 0 0"/>
            <inertia ixx="1" ixy="0" ixz="0" iyy="1" iyz="0" izz="1"/>
        </inertial>
        <collision>
            <origin xyz="0 0 -1.8" rpy="0 0 0"/>
            <geometry>
                <cylinder length="2.7" radius="0.5"/>
            </geometry>
        </collision>
    </link>

    <link name="right_forearm">
        <visual>
            <origin xyz="-0.4 0 -1.6" rpy="0 0 0"/>
            <geometry>
                <cylinder length="2.6" radius="0.35"/>
            </geometry>
            <material name="orange">
                <color rgba="1 0.5 0 1"/>
            </material>
        </visual>
        <inertial>
            <mass value="0.19"/>
            <origin xyz="-0.4 0 -1.6" rpy="0 0 0"/>
            <inertia ixx="1" ixy="0" ixz="0" iyy="1" iyz="0" izz="1"/>
        </inertial>
        <collision>
            <origin xyz="-0.4 0 -1.6" rpy="0 0 0"/>
            <geometry>
                <cylinder length="2.8" radius="0.35"/>
            </geometry>
        </collision>
    </link>

    <link name="right_hand">
        <visual>
            <origin xyz="-0 0 0" rpy="0 0 0"/>
            <geometry>
                <sphere radius="0.5"/>
            </geometry>
            <material name="orange">
                <color rgba="1 0.5 0 1"/>
            </material>
        </visual>
        <inertial>
            <mass value="0.06"/>
            <origin xyz="0 0 0" rpy="0 0 0"/>
            <inertia ixx="1" ixy="0" ixz="0" iyy="1" iyz="0" izz="1"/>
        </inertial>
        <collision>
            <origin xyz="-0 0 0" rpy="0 0 0"/>
            <geometry>
                <sphere radius="0.5"/>
            </geometry>
        </collision>
    </link>

    <link name="left_thigh">
        <visual>
            <origin xyz="0 0 -1.8" rpy="0 0 0"/>
            <geometry>
                <cylinder length="3.2" radius="0.6"/>
            </geometry>
            <material name="yellow">
                <color rgba="1 1 0 1"/>
            </material>
        </visual>
        <inertial>
            <mass value="0.91"/>
            <origin xyz="0 0 -1.8" rpy="0 0 0"/>
            <inertia ixx="1" ixy="0" ixz="0" iyy="1" iyz="0" izz="1"/>
        </inertial>
        <collision>
            <origin xyz="0 0 -1.8" rpy="0 0 0"/>
            <geometry>
                <cylinder length="3.2" radius="0.6"/>
            </geometry>
        </collision>
    </link>

    <link name="left_shin">
        <visual>
            <origin xyz="0.2 0 -2.4" rpy="0 0 0"/>
            <geometry>
                <cylinder length="2.8" radius="0.5"/>
            </geometry>
            <material name="orange">
                <color rgba="1 0.5 0 1"/>
            </material>
        </visual>
        <inertial>
            <mass value="0.48"/>
            <origin xyz="0.2 0 -2.4" rpy="0 0 0"/>
            <inertia ixx="1" ixy="0" ixz="0" iyy="1" iyz="0" izz="1"/>
        </inertial>
        <collision>
            <origin xyz="0.2 0 -2.4" rpy="0 0 0"/>
            <geometry>
                <cylinder length="2.8" radius="0.5"/>
            </geometry>
        </collision>
    </link>

    <link name="left_foot">
        <visual>
            <origin xyz="0.8 0 -0.6" rpy="0 0 0"/>
            <geometry>
                <box size="2.7 0.8 0.4"/>
            </geometry>
            <material name="purple">
                <color rgba="1 0 1 1"/>
            </material>
        </visual>
        <inertial>
            <mass value="0.08"/>
            <origin xyz="0.8 0 -0.6" rpy="0 0 0"/>
            <inertia ixx="1" ixy="0" ixz="0" iyy="1" iyz="0" izz="1"/>
        </inertial>
        <collision>
            <origin xyz="0.8 0 -0.6" rpy="0 0 0"/>
            <geometry>
                <box size="2.7 0.8 0.4"/>
            </geometry>
        </collision>

    </link>

    <link name="right_thigh">
        <visual>
            <origin xyz="0 0 -1.8" rpy="0 0 0"/>
            <geometry>
                <cylinder length="3.2" radius="0.6"/>
            </geometry>
            <material name="yellow">
                <color rgba="1 1 0 1"/>
            </material>
        </visual>
        <inertial>
            <mass value="0.91"/>
            <origin xyz="0 0 -1.8" rpy="0 0 0"/>
            <inertia ixx="1" ixy="0" ixz="0" iyy="1" iyz="0" izz="1"/>
        </inertial>
        <collision>
            <origin xyz="0 0 -1.8" rpy="0 0 0"/>
            <geometry>
                <cylinder length="3.2" radius="0.6"/>
            </geometry>
        </collision>
    </link>

    <link name="right_shin">
        <visual>
            <origin xyz="0.2 0 -2.4" rpy="0 0 0"/>
            <geometry>
                <cylinder length="2.8" radius="0.5"/>
            </geometry>
            <material name="orange">
                <color rgba="1 0.5 0 1"/>
            </material>
        </visual>
        <inertial>
            <mass value="0.48"/>
            <origin xyz="0.2 0 -2.4" rpy="0 0 0"/>
            <inertia ixx="1" ixy="0" ixz="0" iyy="1" iyz="0" izz="1"/>
        </inertial>
        <collision>
            <origin xyz="0.2 0 -2.4" rpy="0 0 0"/>
            <geometry>
                <cylinder length="2.8" radius="0.55"/>
            </geometry>
        </collision>
    </link>

    <link name="right_foot">
        <visual>
            <origin xyz="0.8 0 -0.6" rpy="0 0 0"/>
            <geometry>
                <box size="2.7 0.8 0.4"/>
            </geometry>
            <material name="purple">
                <color rgba="1 0 1 1"/>
            </material>
        </visual>
        <inertial>
            <mass value="0.08"/>
            <origin xyz="0.8 0 -0.6" rpy="0 0 0"/>
            <inertia ixx="1" ixy="0" ixz="0" iyy="1" iyz="0" izz="1"/>
        </inertial>
        <collision>
            <origin xyz="0.8 0 -0.6" rpy="0 0 0"/>
            <geometry>
                <box size="2.7 0.8 0.4"/>
            </geometry>
        </collision>
    </link>

    <link name="neck_link_x">
        <inertial>
            <mass value="0"/>
            <origin xyz="0 0 0" rpy="0 0 0"/>
            <inertia ixx="0.1" ixy="0" ixz="0" iyy="0.1" iyz="0" izz="0.1"/>
        </inertial>
    </link>

    <joint name="neck_y" type="revolute">
        <parent link="chest"/>
        <child link="neck_link_x"/>
        <axis xyz="0 1 0"/>
        <origin xyz="0 0 13" rpy="0 0 0"/>
        <limit lower="-0.25" upper="0.25" velocity="0.5"/>
    </joint>

    <joint name="neck_x" type="revolute">
        <parent link="neck_link_x"/>
        <child link="head"/>
        <axis xyz="1 0 0"/>
        <origin xyz="0 0 0" rpy="0 0 0"/>
        <limit lower="-0.25" upper="0.25" velocity="0.5"/>
    </joint>

    <link name="waist_link_x">
        <inertial>
            <mass value="0"/>
            <origin xyz="0 0 0" rpy="0 0 0"/>
            <inertia ixx="0.1" ixy="0" ixz="0" iyy="0.1" iyz="0" izz="0.1"/>
        </inertial>
    </link>

    <joint name="waist_y" type="revolute">
        <parent link="chest"/>
        <child link="waist_link_x"/>
        <axis xyz="0 1 0"/>
        <origin xyz="0 0 12" rpy="0 0 0"/>
        <limit lower="-1.5" upper="0.2" velocity="0.5"/>
    </joint>

    <link name="waist_link_z">
        <inertial>
            <mass value="0"/>
            <origin xyz="0 0 0" rpy="0 0 0"/>
            <inertia ixx="0.1" ixy="0" ixz="0" iyy="0.1" iyz="0" izz="0.1"/>
        </inertial>
    </link>

    <joint name="waist_x" type="revolute">
        <parent link="waist_link_x"/>
        <child link="waist_link_z"/>
        <axis xyz="1 0 0"/>
        <origin xyz="0 0 0" rpy="0 0 0"/>
        <limit lower="-0.6" upper="0.6" velocity="0.5"/>
    </joint>

    <joint name="waist_z" type="revolute">
        <parent link="waist_link_z"/>
        <child link="hip"/>
        <axis xyz="0 0 1"/>
        <origin xyz="0 0 0" rpy="0 0 0"/>
        <limit lower="-1" upper="1" velocity="0.5"/>
    </joint>

    <link name="left_hip_link_x">
        <inertial>
            <mass value="0"/>
            <origin xyz="0 0 0" rpy="0 0 0"/>
            <inertia ixx="0.1" ixy="0" ixz="0" iyy="0.1" iyz="0" izz="0.1"/>
        </inertial>
    </link>

    <joint name="left_hip_joint_y" type="revolute">
        <parent link="hip"/>
        <child link="left_hip_link_x"/>
        <axis xyz="0 1 0"/>
        <origin xyz="0 1.5 -4.2" rpy="0 0 0"/>
        <limit lower="-2" upper="0" velocity="0.5"/>
    </joint>

    <joint name="left_hip_joint_x" type="revolute">
        <parent link="left_hip_link_x"/>
        <child link="left_thigh"/>
        <axis xyz="1 0 0"/>
        <origin xyz="0 0 0" rpy="0 0 0"/>
        <limit lower="-0.3" upper="1.4" velocity="0.5"/>
    </joint>
    
    <joint name="left_knee" type="revolute">
        <parent link="left_thigh"/>
        <child link="left_shin"/>
        <axis xyz="0 1 0"/>
        <origin xyz="-0.2 0 -3.2" rpy="0 0 0"/>
        <limit lower="0" upper="2.3" velocity="0.5"/>
    </joint>

    <link name="left_ankle_link">
        <inertial>
            <mass value="0"/>
            <origin xyz="0 0 0" rpy="0 0 0"/>
            <inertia ixx="0.1" ixy="0" ixz="0" iyy="0.1" iyz="0" izz="0.1"/>
        </inertial>
    </link>

    <joint name="left_ankle_y" type="revolute">
        <parent link="left_shin"/>
        <child link="left_ankle_link"/>
        <axis xyz="0 1 0"/>
        <origin xyz="0 0 -3.8" rpy="0 0 0"/>
        <limit lower="-0.7" upper="0.7" velocity="0.5"/>
    </joint>

    <joint name="left_ankle_x" type="revolute">
        <parent link="left_ankle_link"/>
        <child link="left_foot"/>
        <axis xyz="1 0 0"/>
        <origin xyz="0 0 0" rpy="0 0 0"/>
        <limit lower="-0.3" upper="0.3" velocity="0.5"/>
    </joint>

    <link name="right_hip_link_x">
        <inertial>
            <mass value="0"/>
            <origin xyz="0 0 0" rpy="0 0 0"/>
            <inertia ixx="0.1" ixy="0" ixz="0" iyy="0.1" iyz="0" izz="0.1"/>
        </inertial>
    </link>

    <joint name="right_hip_joint_y" type="revolute">
        <parent link="hip"/>
        <child link="right_hip_link_x"/>
        <axis xyz="0 1 0"/>
        <origin xyz="0 -1.5 -4.2" rpy="0 0 0"/>
        <limit lower="0" upper="2" velocity="0.5"/>
    </joint>

    <joint name="right_hip_joint_x" type="revolute">
        <parent link="right_hip_link_x"/>
        <child link="right_thigh"/>
        <axis xyz="1 0 0"/>
        <origin xyz="0 0 0" rpy="0 0 0"/>
        <limit lower="-1.4" upper="0.3" velocity="0.5"/>
    </joint>

    <joint name="right_knee" type="revolute">
        <parent link="right_thigh"/>
        <child link="right_shin"/>
        <axis xyz="0 1 0"/>
        <origin xyz="-0.2 0 -3.2" rpy="0 0 0"/>
        <limit lower="0" upper="2.3" velocity="0.5"/>
    </joint>

    <link name="right_ankle_link">
        <inertial>
            <mass value="0"/>
            <origin xyz="0 0 0" rpy="0 0 0"/>
            <inertia ixx="0.1" ixy="0" ixz="0" iyy="0.1" iyz="0" izz="0.1"/>
        </inertial>
    </link>

    <joint name="right_ankle_y" type="revolute">
        <parent link="right_shin"/>
        <child link="right_ankle_link"/>
        <axis xyz="0 1 0"/>
        <origin xyz="0 0 -3.8" rpy="0 0 0"/>
        <limit lower="-0.7" upper="0.7" velocity="0.5"/>
    </joint>

    <joint name="right_ankle_x" type="revolute">
        <parent link="right_ankle_link"/>
        <child link="right_foot"/>
        <axis xyz="0 1 0"/>
        <origin xyz="0 0 0" rpy="0 0 0"/>
        <limit lower="-0.3" upper="0.3" velocity="0.5"/>
    </joint>

    <link name="left_should_link_x">
        <inertial>
            <mass value="0"/>
            <origin xyz="0 0 0" rpy="0 0 0"/>
            <inertia ixx="0.1" ixy="0" ixz="0" iyy="0.1" iyz="0" izz="0.1"/>
        </inertial>
    </link>

    <joint name="left_shoulder_y" type="revolute">
        <parent link="chest"/>
        <child link="left_should_link_x"/>
        <axis xyz="0 1 0"/>
        <origin xyz="0 2.5 13.4" rpy="0 0 0"/>
        <limit lower="-3.1" upper="0.7" velocity="0.5"/>
    </joint>

    <joint name="left_shoulder_x" type="revolute">
        <parent link="left_should_link_x"/>
        <child link="left_upper_arm"/>
        <axis xyz="1 0 0"/>
        <origin xyz="0 0 0" rpy="0.1 0 0"/>
        <limit lower="-0.5" upper="1.46" velocity="0.5"/>
    </joint>

    <joint name="left_elbow" type="revolute">
        <parent link="left_upper_arm"/>
        <child link="left_forearm"/>
        <axis xyz="0 1 0"/>
        <origin xyz="0.4 0 -3.2" rpy="0 0 0"/>
        <limit lower="-2.8" upper="0" velocity="0.5"/>
    </joint>

    <joint name="left_wrist" type="fixed">
        <parent link="left_forearm"/>
        <child link="left_hand"/>
        <origin xyz="-0.4 0 -3.5" rpy="0 0 0"/>
    </joint>

    <link name="right_should_link_x">
        <inertial>
            <mass value="0"/>
            <origin xyz="0 0 0" rpy="0 0 0"/>
            <inertia ixx="0.1" ixy="0" ixz="0" iyy="0.1" iyz="0" izz="0.1"/>
        </inertial>
    </link>

    <joint name="right_shoulder_y" type="revolute">
        <parent link="chest"/>
        <child link="right_should_link_x"/>
        <axis xyz="0 1 0"/>
        <origin xyz="0 -2.5 13.4" rpy="0 0 0"/>
        <limit lower="-3.1" upper="0.7" velocity="0.5"/>
    </joint>

    <joint name="right_shoulder_x" type="revolute">
        <parent link="right_should_link_x"/>
        <child link="right_upper_arm"/>
        <axis xyz="1 0 0"/>
        <origin xyz="0 0 0" rpy="-0.1 0 0"/>
        <limit lower="-1.46" upper="0.5" velocity="0.5"/>
    </joint>

    <joint name="right_elbow" type="revolute">
        <parent link="right_upper_arm"/>
        <child link="right_forearm"/>
        <axis xyz="0 1 0"/>
        <origin xyz="0.4 0 -3.2" rpy="0 0 0"/>
        <limit lower="-2.8" upper="0" velocity="0.5"/>
    </joint>

    <joint name="right_wrist" type="fixed">
        <parent link="right_forearm"/>
        <child link="right_hand"/>
        <origin xyz="-0.4 0 -3.5" rpy="0 0 0"/>
    </joint>

</robot>